{"name": "Test01: Verify Invalid Login to Parabank", "status": "broken", "statusDetails": {"message": "TypeError: WebDriver.__init__() got an unexpected keyword argument 'service'", "trace": "request = <SubRequest 'init_web_driver' for <Function test_verify_login_error_parabank[nir-12344]>>\n\n    @pytest.fixture(scope='class')\n    def init_web_driver(request):\n        if get_data('Execute_Applitools').lower() == 'yes':\n>           globals()['driver'] = get_web_driver()\n\ntests_cases\\conftest.py:30: \n_ _ _ _ _ _ _ _ _ _ _ _ _ _ _ _ _ _ _ _ _ _ _ _ _ _ _ _ _ _ _ _ _ _ _ _ _ _ _ _\ntests_cases\\conftest.py:112: in get_web_driver\n    driver = get_edge()\n_ _ _ _ _ _ _ _ _ _ _ _ _ _ _ _ _ _ _ _ _ _ _ _ _ _ _ _ _ _ _ _ _ _ _ _ _ _ _ _\n\n    def get_edge():\n        srv = Service(EdgeChromiumDriverManager().install())  # selenium 4\n>       edge_driver = selenium.webdriver.Edge(service=srv)  # selenium 4\nE       TypeError: WebDriver.__init__() got an unexpected keyword argument 'service'\n\ntests_cases\\conftest.py:144: TypeError"}, "description": "This test verifies that attempting to log in with invalid credentials results in error message.", "parameters": [{"name": "user", "value": "'dafna'"}, {"name": "password", "value": "'12342'"}], "start": 1734710814924, "stop": 1734710814924, "uuid": "891a9bb2-543b-4895-ad47-bcfa63e72f29", "historyId": "732c8cf7a3f137f0f625e6b747e5c3c8", "testCaseId": "ec6319908d3f536bfe8e97d1c3cb4127", "fullName": "tests_cases.test_web.TestWeb#test_verify_login_error_parabank", "labels": [{"name": "tag", "value": "@pytest.mark.usefixtures('init_web_driver')"}, {"name": "parentSuite", "value": "tests_cases"}, {"name": "suite", "value": "test_web"}, {"name": "subSuite", "value": "TestWeb"}, {"name": "host", "value": "DESKTOP-DHGB96Q"}, {"name": "thread", "value": "16316-MainThread"}, {"name": "framework", "value": "pytest"}, {"name": "language", "value": "cpython3"}, {"name": "package", "value": "tests_cases.test_web"}]}